<?xml version="1.0"?>
<robot xmlns:xacro="http://www.ros.org/wiki/xacro" name="mobi">

  <!-- Hier werden die Dateien importiert. -->
  <xacro:include filename="$(find mobi_description)/urdf/common_properties.xacro" />
  <xacro:include filename="$(find mobi_description)/urdf/mobi.gazebo.xacro" /> 
  <!-- <xacro:include filename="$(find mobi_ros2)/urdf/macro.tower.urdf.xacro" /> -->

  <!-- Farben vom Roboter f체r RVIZ-->
  <xacro:materials_rviz />

  <!-- Base Koordinatensystem als Referenz -->
  <link name="base_link"/>

  <joint name="base_footprint_joint" type="fixed">
    <parent link="base_link"/>
    <child link="base_footprint" />
    <origin xyz="0 0 0" rpy="0 0 0"/>
  </joint>

  <link name="base_footprint"/>

  <!-- Mobi Plattform  -->
  
  <joint name="chassis_joint" type="fixed">
    <parent link="base_link"/>
    <child link="chassis_link" />
    <origin xyz="0 0 0.03" rpy="0 0 0"/>
  </joint>

  <link name="chassis_link">
      <visual>
	    <origin rpy="0 0 0" xyz="0 0 0.0415" />
      <geometry>
        <box size="0.285 0.198 0.083"/>
      </geometry>
	    <material name="yellow"/>
    </visual>

    <collision>
      <origin rpy="0 0 0" xyz="0 0 0.0415" />
      <geometry>
        <box size="0.285 0.198 0.083"/>
      </geometry>
    </collision>

    <inertial>
      <mass value="10"/>
      <origin rpy="0 0 0" xyz="0 0 0.0415"/>
       <inertia ixx="0.03267" ixy="0" ixz="0" iyy="0.067688" iyz="0" izz="0.100358"/> 
    </inertial>
  </link>


  <!-- 4 R채der werden hier hinzugef체gt
  Links vorne 
  Links hinten 
  Rechts vorne 
  Rechts hinten
  -->
  <joint name="front_left_wheel_joint" type="continuous">
        <origin xyz="0.0975 0.107 0.023" rpy="1.5708 0 3.1415"/>
        <parent link="chassis_link"/>
        <child link="front_left_wheel_link"/>
        <axis xyz="0 0 -1"/>
  </joint>

  <link name="front_left_wheel_link">
    <visual>
	    <origin rpy="0 0 0" xyz="0 0 0.025" />
      <geometry>
        <cylinder radius="0.05" length="0.05"/>
      </geometry>
	    <material name="dark_gray"/>
    </visual>

    <collision>
      <origin rpy="0 0 0" xyz="0 0 0.025" />
      <geometry>
        <cylinder radius="0.05" length="0.05"/>
      </geometry>
    </collision>

    <inertial>
      <mass value="0.2"/>
      <origin rpy="0 0 0" xyz="0 0 0.025"/>
      <inertia ixx="0.000167" ixy="0" ixz="0" iyy="0.000167" iyz="0" izz="0.00025"/>
    </inertial>
  </link>

  <joint name="rear_left_wheel_joint" type="continuous">
        <origin xyz="-0.0975 0.107 0.023" rpy="1.5708 0 3.1415"/>
        <parent link="chassis_link"/>
        <child link="rear_left_wheel_link"/>
        <axis xyz="0 0 -1"/>
  </joint>

  <link name="rear_left_wheel_link">
    <visual>
	    <origin rpy="0 0 0" xyz="0 0 0.025" />
      <geometry>
        <cylinder radius="0.05" length="0.05"/>
      </geometry>
	    <material name="dark_gray"/>
    </visual>

    <collision>
      <origin rpy="0 0 0" xyz="0 0 0.025" />
      <geometry>
        <cylinder radius="0.05" length="0.05"/>
      </geometry>
    </collision>

    <inertial>
      <mass value="0.2"/>
      <origin rpy="0 0 0" xyz="0 0 0.025"/>
      <inertia ixx="0.000167" ixy="0" ixz="0" iyy="0.000167" iyz="0" izz="0.00025"/>
    </inertial>
  </link>

  <joint name="front_right_wheel_joint" type="continuous">
        <origin xyz="0.0975 -0.107 0.023" rpy="1.5708 0 0"/>
        <parent link="chassis_link"/>
        <child link="front_right_wheel_link"/>
        <axis xyz="0 0 1"/>
  </joint>

  <link name="front_right_wheel_link">
    <visual>
	    <origin rpy="0 0 0" xyz="0 0 0.025" />
      <geometry>
        <cylinder radius="0.05" length="0.05"/>
      </geometry>
	    <material name="dark_gray"/>
    </visual>

    <collision>
      <origin rpy="0 0 0" xyz="0 0 0.025" />
      <geometry>
        <cylinder radius="0.05" length="0.05"/>
      </geometry>
    </collision>

    <inertial>
      <mass value="0.2"/>
      <origin rpy="0 0 0" xyz="0 0 0.025"/>
      <inertia ixx="0.000167" ixy="0" ixz="0" iyy="0.000167" iyz="0" izz="0.00025"/>
    </inertial>
  </link>

  <joint name="rear_right_wheel_joint" type="continuous">
        <origin xyz="-0.0975 -0.107 0.023" rpy="1.5708 0 0"/>
        <parent link="chassis_link"/>
        <child link="rear_right_wheel_link"/>
        <axis xyz="0 0 1"/>
  </joint>

  <link name="rear_right_wheel_link">
    <visual>
	    <origin rpy="0 0 0" xyz="0 0 0.025" />
      <geometry>
        <cylinder radius="0.05" length="0.05"/>
      </geometry>
	    <material name="dark_gray"/>
    </visual>

    <collision>
      <origin rpy="0 0 0" xyz="0 0 0.025" />
      <geometry>
        <cylinder radius="0.05" length="0.05"/>
      </geometry>
    </collision>

    <inertial>
      <mass value="0.2"/>
      <origin rpy="0 0 0" xyz="0 0 0.025"/>
      <inertia ixx="0.000167" ixy="0" ixz="0" iyy="0.000167" iyz="0" izz="0.00025"/>
    </inertial>
  </link>

  <!-- Obere Abschnitt von Mobi  -->
  

  <joint name="housing_joint" type="fixed">
        <origin xyz="0 0 0.083" rpy="0 0 0"/>
        <parent link="chassis_link"/>
        <child link="housing_link"/>
  </joint>

  <link name="housing_link">
    <visual>
	    <origin xyz="0 0 0.03575" rpy="0 0 0" />
      <geometry>
        <box size="0.167 0.1556 0.0715"/>  
      </geometry>
	    <material name="dark_gray"/>
    </visual>
  </link>

  <joint name="cylinder_1_joint" type="fixed">
        <origin xyz="0.05 0.05 0.0715" rpy="0 0 0"/>
        <parent link="housing_link"/>
        <child link="cylinder_1_link"/>
  </joint>

  <link name="cylinder_1_link">
    <visual>
	    <origin xyz="0 0 0.025" rpy="0 0 0" />
      <geometry>
        <cylinder radius="0.006" length="0.05"/>
      </geometry>
	    <material name="light_gray"/>
    </visual>
  </link>

  <joint name="cylinder_2_joint" type="fixed">
        <origin xyz="-0.05 0.05 0.0715" rpy="0 0 0"/>
        <parent link="housing_link"/>
        <child link="cylinder_2_link"/>
  </joint>

  <link name="cylinder_2_link">
    <visual>
	    <origin xyz="0 0 0.025" rpy="0 0 0" />
      <geometry>
        <cylinder radius="0.006" length="0.05"/>
      </geometry>
	    <material name="light_gray"/>
    </visual>
  </link>

  <joint name="cylinder_3_joint" type="fixed">
        <origin xyz="0.05 -0.05 0.0715" rpy="0 0 0"/>
        <parent link="housing_link"/>
        <child link="cylinder_3_link"/>
  </joint>

  <link name="cylinder_3_link">
    <visual>
	    <origin xyz="0 0 0.025" rpy="0 0 0" />
      <geometry>
        <cylinder radius="0.006" length="0.05"/>
      </geometry>
	    <material name="light_gray"/>
    </visual>
  </link>

  <joint name="cylinder_4_joint" type="fixed">
        <origin xyz="-0.05 -0.05 0.0715" rpy="0 0 0"/>
        <parent link="housing_link"/>
        <child link="cylinder_4_link"/>
  </joint>

  <link name="cylinder_4_link">
    <visual>
	    <origin xyz="0 0 0.025" rpy="0 0 0" />
      <geometry>
        <cylinder radius="0.006" length="0.05"/>
      </geometry>
	    <material name="light_gray"/>
    </visual>
  </link>

  <joint name="plate_joint" type="fixed">
        <origin xyz="0 0 0.1215" rpy="0 0 0"/>
        <parent link="housing_link"/>
        <child link="plate_link"/>
  </joint>

  <link name="plate_link">
    <visual>
	    <origin xyz="0 0 0.006" rpy="0 0 0" />
      <geometry>
        <box size="0.150 0.150 0.012"/>  
      </geometry>
	    <material name="light_gray"/>
    </visual>
  </link>

  <joint name="lidar_joint" type="fixed">
        <origin xyz="0 0 0.012" rpy="0 0 0"/>
        <parent link="plate_link"/>
        <child link="lidar_link"/>
  </joint>

  <link name="lidar_link">
    <visual>
	    <origin xyz="0 0 0.02" rpy="0 0 0" />
      <geometry>
        <cylinder radius="0.0375" length="0.04"/>
      </geometry>
	    <material name="gray"/>
    </visual>
  </link>

  <!-- Hier werden Links f체r die Sensoren definiert. -->
  <joint name="imu_joint" type="fixed">
    <origin xyz="0 0 0" rpy="0 0 0"/>
    <parent link="housing_link"/>
    <child link="imu_link"/>
  </joint>

  <link name="imu_link"/>

  <joint name="scan_joint" type="fixed">
    <origin xyz="0 0 0.03" rpy="0 0 0"/>
    <parent link="lidar_link"/>
    <child link="scan_link"/>
  </joint>

  <link name="scan_link"/>

  
</robot>